<?xml version="1.0" encoding="utf-8" ?>
<!-- This URDF was automatically created by SolidWorks to URDF Exporter! Originally created by Stephen Brawner (brawner@gmail.com) 
     Commit Version: 1.6.0-1-g15f4949  Build Version: 1.6.7594.29634
     For more information, please see http://wiki.ros.org/sw_urdf_exporter -->
<robot name="Dorna_2_Simulation">
    <link name="base_link">
        
<inertial>
            <origin xyz="-0.033591 -2.3591E-09 0.0453" rpy="0 0 0" />
            <mass value="0.1459" />
            <inertia ixx="0.00023804" ixy="6.3486E-12" ixz="1.2702E-05" iyy="0.0002306" iyz="-6.8648E-12" izz="0.00013538" />
        </inertial>

        <visual>
            <origin xyz="0 0 0" rpy="0 0 0" />
            <geometry>
                <mesh filename="package://Dorna_2_Simulation/meshes/base_link.STL" />
            </geometry>
            <material name="">
                <color rgba="0.79216 0.81961 0.93333 1" />
            </material>
        </visual>
        <collision>
            <origin xyz="0 0 0" rpy="0 0 0" />
            <geometry>
                <mesh filename="package://Dorna_2_Simulation/meshes/base_link_Collision.STL" />
            </geometry>
        </collision>
    </link>
    <link name="link1">
        
<inertial>
            <origin xyz="-0.022037 7.1203E-05 0.1186" rpy="0 0 0" />
            <mass value="0.70203" />
            <inertia ixx="0.0016762" ixy="0.00012689" ixz="-0.00047838" iyy="0.0028093" iyz="-3.1576E-05" izz="0.0029334" />
        </inertial>

        <visual>
            <origin xyz="0 0 0" rpy="0 0 0" />
            <geometry>
                <mesh filename="package://Dorna_2_Simulation/meshes/link1.STL" />
            </geometry>
            <material name="">
                <color rgba="0.79216 0.81961 0.93333 1" />
            </material>
        </visual>
        <collision>
            <origin xyz="0 0 0" rpy="0 0 0" />
            <geometry>
                <mesh filename="package://Dorna_2_Simulation/meshes/link1_Collision.STL" />
            </geometry>
        </collision>
    </link>
    <joint name="joint1" type="revolute">
        <origin xyz="-0.036 0 0.014163" rpy="0 0 0" />
        <parent link="base_link" />
        <child link="link1" />
        <axis xyz="0 0 1" />
        <limit lower="-2.7925" upper="3.1416" effort="10" velocity="10.472" />
    </joint>
    <link name="link2">
        
<inertial>
            <origin xyz="0.033004 -0.045646 1.2537E-06" rpy="0 0 0" />
            <mass value="0.32464" />
            <inertia ixx="0.00048989" ixy="6.9761E-05" ixz="1.9504E-08" iyy="0.0017419" iyz="-1.0012E-08" izz="0.0020909" />
        </inertial>

        <visual>
            <origin xyz="0 0 0" rpy="0 0 0" />
            <geometry>
                <mesh filename="package://Dorna_2_Simulation/meshes/link2.STL" />
            </geometry>
            <material name="">
                <color rgba="0.79216 0.81961 0.93333 1" />
            </material>
        </visual>
        <collision>
            <origin xyz="0 0 0" rpy="0 0 0" />
            <geometry>
                <mesh filename="package://Dorna_2_Simulation/meshes/link2_Collision.STL" />
            </geometry>
        </collision>
    </link>
    <joint name="joint2" type="revolute">
        <origin xyz="0.095476 0.04845 0.1923" rpy="0 0 0" />
        <parent link="link1" />
        <child link="link2" />
        <axis xyz="0 1 0" />
        <limit lower="-3.1415" upper="1.5708" effort="10" velocity="7.854" />
    </joint>
    <link name="link3">
        
<inertial>
            <origin xyz="0.021064 -0.039486 -4.7847E-08" rpy="0 0 0" />
            <mass value="0.27313" />
            <inertia ixx="0.00021713" ixy="2.2442E-05" ixz="3.6407E-08" iyy="0.00085068" iyz="-1.2633E-08" izz="0.00098072" />
        </inertial>

        <visual>
            <origin xyz="0 0 0" rpy="0 0 0" />
            <geometry>
                <mesh filename="package://Dorna_2_Simulation/meshes/link3.STL" />
            </geometry>
            <material name="">
                <color rgba="0.79216 0.81961 0.93333 1" />
            </material>
        </visual>
        <collision>
            <origin xyz="0 0 0" rpy="0 0 0" />
            <geometry>
                <mesh filename="package://Dorna_2_Simulation/meshes/link3_Collision.STL" />
            </geometry>
        </collision>
    </link>
    <joint name="joint3" type="revolute">
        <origin xyz="0.2032 -0.00735 0" rpy="0 0 0" />
        <parent link="link2" />
        <child link="link3" />
        <axis xyz="0 -1 0" />
        <limit lower="-2.4784" upper="2.4784" effort="10" velocity="7.854" />
    </joint>
    <link name="link4">
        
<inertial>
            <origin xyz="-5.9653E-10 -0.0411 1.003E-09" rpy="0 0 0" />
            <mass value="0.076836" />
            <inertia ixx="5.639E-05" ixy="2.2837E-13" ixz="6.7695E-14" iyy="1.719E-05" iyz="1.776E-12" izz="5.5885E-05" />
        </inertial>

        <visual>
            <origin xyz="0 0 0" rpy="0 0 0" />
            <geometry>
                <mesh filename="package://Dorna_2_Simulation/meshes/link4.STL" />
            </geometry>
            <material name="">
                <color rgba="0.79216 0.81961 0.93333 1" />
            </material>
        </visual>
        <collision>
            <origin xyz="0 0 0" rpy="0 0 0" />
            <geometry>
                <mesh filename="package://Dorna_2_Simulation/meshes/link4_Collision.STL" />
            </geometry>
        </collision>
    </link>
    <joint name="joint4" type="revolute">
        <origin xyz="0.1524 0 0" rpy="0 0 0" />
        <parent link="link3" />
        <child link="link4" />
        <axis xyz="0 -1 0" />
        <limit lower="-2.3562" upper="2.3562" effort="10" velocity="34.907" />
    </joint>
    <link name="link5">
        
<inertial>
            <origin xyz="0.019873 -6.4374E-06 -0.039605" rpy="0 0 0" />
            <mass value="0.41658" />
            <inertia ixx="0.00014403" ixy="1.1578E-09" ixz="6.5087E-06" iyy="0.00014394" iyz="2.8154E-10" izz="0.00012184" />
        </inertial>

        <visual>
            <origin xyz="0 0 0" rpy="0 0 0" />
            <geometry>
                <mesh filename="package://Dorna_2_Simulation/meshes/link5.STL" />
            </geometry>
            <material name="">
                <color rgba="0.79216 0.81961 0.93333 1" />
            </material>
        </visual>
        <collision>
            <origin xyz="0 0 0" rpy="0 0 0" />
            <geometry>
                <mesh filename="package://Dorna_2_Simulation/meshes/link5_Collision.STL" />
            </geometry>
        </collision>
    </link>
    <joint name="joint5" type="revolute">
        <origin xyz="0.048937 -0.0411 0" rpy="0 0 0" />
        <parent link="link4" />
        <child link="link5" />
        <axis xyz="-1 0 0" />
        <limit lower="-6.2832" upper="6.2832" effort="10" velocity="34.907" />
    </joint>
    
<transmission name="trans_joint1">
        <type>transmission_interface/SimpleTransmission</type>
        <joint name="joint1">
            <hardwareInterface>hardware_interface/EffortJointInterface</hardwareInterface>
        </joint>
        <actuator name="joint1_motor">
            <hardwareInterface>hardware_interface/EffortJointInterface</hardwareInterface>
            <mechanicalReduction>1</mechanicalReduction>
        </actuator>
    </transmission>
    <transmission name="trans_joint2">
        <type>transmission_interface/SimpleTransmission</type>
        <joint name="joint2">
            <hardwareInterface>hardware_interface/EffortJointInterface</hardwareInterface>
        </joint>
        <actuator name="joint2_motor">
            <hardwareInterface>hardware_interface/EffortJointInterface</hardwareInterface>
            <mechanicalReduction>1</mechanicalReduction>
        </actuator>
    </transmission>
    <transmission name="trans_joint3">
        <type>transmission_interface/SimpleTransmission</type>
        <joint name="joint3">
            <hardwareInterface>hardware_interface/EffortJointInterface</hardwareInterface>
        </joint>
        <actuator name="joint3_motor">
            <hardwareInterface>hardware_interface/EffortJointInterface</hardwareInterface>
            <mechanicalReduction>1</mechanicalReduction>
        </actuator>
    </transmission>
    <transmission name="trans_joint4">
        <type>transmission_interface/SimpleTransmission</type>
        <joint name="joint4">
            <hardwareInterface>hardware_interface/EffortJointInterface</hardwareInterface>
        </joint>
        <actuator name="joint4_motor">
            <hardwareInterface>hardware_interface/EffortJointInterface</hardwareInterface>
            <mechanicalReduction>1</mechanicalReduction>
        </actuator>
    </transmission>
    <transmission name="trans_joint5">
        <type>transmission_interface/SimpleTransmission</type>
        <joint name="joint5">
            <hardwareInterface>hardware_interface/EffortJointInterface</hardwareInterface>
        </joint>
        <actuator name="joint5_motor">
            <hardwareInterface>hardware_interface/EffortJointInterface</hardwareInterface>
            <mechanicalReduction>1</mechanicalReduction>
        </actuator>
    </transmission>
    <gazebo>
        <plugin name="gazebo_ros_control" filename="libgazebo_ros_control.so">
            <robotNamespace>/</robotNamespace>
        </plugin>
    </gazebo>
</robot>
