<?xml version="1.0" encoding="utf-8"?>
<!-- This URDF was automatically created by SolidWorks to URDF Exporter! Originally created by Stephen Brawner (brawner@gmail.com) 
     Commit Version: 1.6.0-1-g15f4949  Build Version: 1.6.7594.29634
     For more information, please see http://wiki.ros.org/sw_urdf_exporter -->
<robot
  name="Dorna_2_URDF">
  <link
    name="base_link">
    <inertial>
      <origin
        xyz="0.12698 1.4251E-06 0.055207"
        rpy="0 0 0" />
      <mass
        value="20.928" />
      <inertia
        ixx="0.60154"
        ixy="8.1377E-09"
        ixz="1.943E-05"
        iyy="0.62155"
        iyz="9.3581E-07"
        izz="1.1706" />
    </inertial>
    <visual>
      <origin
        xyz="0 0 0"
        rpy="0 0 0" />
      <geometry>
        <mesh
          filename="package://Dorna_2_URDF/meshes/base_link.STL" />
      </geometry>
      <material
        name="">
        <color
          rgba="0.79216 0.81961 0.93333 1" />
      </material>
    </visual>
    <collision>
      <origin
        xyz="0 0 0"
        rpy="0 0 0" />
      <geometry>
        <mesh
          filename="package://Dorna_2_URDF/meshes/base_link_Collision.STL" />
      </geometry>
    </collision>
  </link>
  <link
    name="Link_1">
    <inertial>
      <origin
        xyz="-0.022037 7.1084E-05 0.13277"
        rpy="0 0 0" />
      <mass
        value="0.70203" />
      <inertia
        ixx="0.0016762"
        ixy="0.00012689"
        ixz="-0.00047838"
        iyy="0.0028093"
        iyz="-3.1578E-05"
        izz="0.0029334" />
    </inertial>
    <visual>
      <origin
        xyz="0 0 0"
        rpy="0 0 0" />
      <geometry>
        <mesh
          filename="package://Dorna_2_URDF/meshes/Link_1.STL" />
      </geometry>
      <material
        name="">
        <color
          rgba="0.79216 0.81961 0.93333 1" />
      </material>
    </visual>
    <collision>
      <origin
        xyz="0 0 0"
        rpy="0 0 0" />
      <geometry>
        <mesh
          filename="package://Dorna_2_URDF/meshes/Link_1_Collision.STL" />
      </geometry>
    </collision>
  </link>
  <joint
    name="Joint_0"
    type="revolute">
    <origin
      xyz="0 0 0"
      rpy="0 0 0" />
    <parent
      link="base_link" />
    <child
      link="Link_1" />
    <axis
      xyz="0 0 1" />
    <limit
      lower="-3.1416"
      upper="2.7925"
      effort="10"
      velocity="10.472" />
  </joint>
  <link
    name="Link_2">
    <inertial>
      <origin
        xyz="-0.033002 -0.047997 0.00035643"
        rpy="0 0 0" />
      <mass
        value="0.32464" />
      <inertia
        ixx="0.00049008"
        ixy="-6.9759E-05"
        ixz="1.7367E-05"
        iyy="0.0017419"
        iyz="7.6578E-07"
        izz="0.0020907" />
    </inertial>
    <visual>
      <origin
        xyz="0 0 0"
        rpy="0 0 0" />
      <geometry>
        <mesh
          filename="package://Dorna_2_URDF/meshes/Link_2.STL" />
      </geometry>
      <material
        name="">
        <color
          rgba="0.79216 0.81961 0.93333 1" />
      </material>
    </visual>
    <collision>
      <origin
        xyz="0 0 0"
        rpy="0 0 0" />
      <geometry>
        <mesh
          filename="package://Dorna_2_URDF/meshes/Link_2_Collision.STL" />
      </geometry>
    </collision>
  </link>
  <joint
    name="Joint_1"
    type="revolute">
    <origin
      xyz="0.095476 0.0508 0.20647"
      rpy="0 0 0" />
    <parent
      link="Link_1" />
    <child
      link="Link_2" />
    <axis
      xyz="0 1 0" />
    <limit
      lower="0"
      upper="4.7123"
      effort="10"
      velocity="7.854" />
  </joint>
  <link
    name="Link_3">
    <inertial>
      <origin
        xyz="0.016739 -0.042836 0.012788"
        rpy="0 0 0" />
      <mass
        value="0.27313" />
      <inertia
        ixx="0.00049852"
        ixy="1.7841E-05"
        ixz="-0.00036836"
        iyy="0.00085068"
        iyz="1.3614E-05"
        izz="0.00069932" />
    </inertial>
    <visual>
      <origin
        xyz="0 0 0"
        rpy="0 0 0" />
      <geometry>
        <mesh
          filename="package://Dorna_2_URDF/meshes/Link_3.STL" />
      </geometry>
      <material
        name="">
        <color
          rgba="0.79216 0.81961 0.93333 1" />
      </material>
    </visual>
    <collision>
      <origin
        xyz="0 0 0"
        rpy="0 0 0" />
      <geometry>
        <mesh
          filename="package://Dorna_2_URDF/meshes/Link_3_Collision.STL" />
      </geometry>
    </collision>
  </link>
  <joint
    name="Joint_2"
    type="revolute">
    <origin
      xyz="-0.20319 -0.00635 0.0022018"
      rpy="0 0 0" />
    <parent
      link="Link_2" />
    <child
      link="Link_3" />
    <axis
      xyz="0 1 0" />
    <limit
      lower="-4.9567"
      upper="0"
      effort="10"
      velocity="7.854" />
  </joint>
  <link
    name="Link_4">
    <inertial>
      <origin
        xyz="7.2482E-10 -0.037338 9.1913E-10"
        rpy="0 0 0" />
      <mass
        value="0.076836" />
      <inertia
        ixx="5.6381E-05"
        ixy="-9.1643E-15"
        ixz="-6.6324E-08"
        iyy="1.719E-05"
        iyz="-1.7906E-12"
        izz="5.5894E-05" />
    </inertial>
    <visual>
      <origin
        xyz="0 0 0"
        rpy="0 0 0" />
      <geometry>
        <mesh
          filename="package://Dorna_2_URDF/meshes/Link_4.STL" />
      </geometry>
      <material
        name="">
        <color
          rgba="0.79216 0.81961 0.93333 1" />
      </material>
    </visual>
    <collision>
      <origin
        xyz="0 0 0"
        rpy="0 0 0" />
      <geometry>
        <mesh
          filename="package://Dorna_2_URDF/meshes/Link_4_Collision.STL" />
      </geometry>
    </collision>
  </link>
  <joint
    name="Joint_3"
    type="revolute">
    <origin
      xyz="0.1211 -0.007112 0.092521"
      rpy="0 0 0" />
    <parent
      link="Link_3" />
    <child
      link="Link_4" />
    <axis
      xyz="0 -1 0" />
    <limit
      lower="-4.71239"
      upper="0"
      effort="10"
      velocity="34.907" />
  </joint>
  <link
    name="Link_5">
    <inertial>
      <origin
        xyz="-0.07942 -0.033145 0.010648"
        rpy="0 0 0" />
      <mass
        value="0.28989" />
      <inertia
        ixx="0.00010848"
        ixy="-2.7004E-06"
        ixz="1.9943E-07"
        iyy="8.8786E-05"
        iyz="3.3745E-07"
        izz="0.00010985" />
    </inertial>
    <visual>
      <origin
        xyz="0 0 0"
        rpy="0 0 0" />
      <geometry>
        <mesh
          filename="package://Dorna_2_URDF/meshes/Link_5.STL" />
      </geometry>
      <material
        name="">
        <color
          rgba="0.79216 0.81961 0.93333 1" />
      </material>
    </visual>
    <collision>
      <origin
        xyz="0 0 0"
        rpy="0 0 0" />
      <geometry>
        <mesh
          filename="package://Dorna_2_URDF/meshes/Link_5_Collision.STL" />
      </geometry>
    </collision>
  </link>
  <joint
    name="Joint_4"
    type="continuous">
    <origin
      xyz="0.012588 -0.037338 -0.0016842"
      rpy="0 0 0" />
    <parent
      link="Link_4" />
    <child
      link="Link_5" />
    <axis
      xyz="0.99117 0 -0.13261" />
    <limit
      effort="10"
      velocity="34.907" />
  </joint>
  <link
    name="Link_6">
    <inertial>
      <origin
        xyz="9.3504E-06 0.051551 -1.3987E-06"
        rpy="0 0 0" />
      <mass
        value="0.054936" />
      <inertia
        ixx="7.5554E-06"
        ixy="-6.5216E-09"
        ixz="-6.8484E-09"
        iyy="1.0764E-06"
        iyz="8.0904E-10"
        izz="7.505E-06" />
    </inertial>
    <visual>
      <origin
        xyz="0 0 0"
        rpy="0 0 0" />
      <geometry>
        <mesh
          filename="package://Dorna_2_URDF/meshes/Link_6.STL" />
      </geometry>
      <material
        name="">
        <color
          rgba="0.64706 0.61961 0.58431 1" />
      </material>
    </visual>
    <collision>
      <origin
        xyz="0 0 0"
        rpy="0 0 0" />
      <geometry>
        <mesh
          filename="package://Dorna_2_URDF/meshes/Link_6_Collision.STL" />
      </geometry>
    </collision>
  </link>
  <joint
    name="Joint_5"
    type="continuous">
    <origin
      xyz="-0.08835 -0.12269 0.011821"
      rpy="0 0 0" />
    <parent
      link="Link_5" />
    <child
      link="Link_6" />
    <axis
      xyz="0 1 0" />
  </joint>
</robot>