<?xml version="1.0" encoding="utf-8"?>
<!-- This URDF was automatically created by SolidWorks to URDF Exporter! Originally created by Stephen Brawner (brawner@gmail.com) 
     Commit Version: 1.6.0-1-g15f4949  Build Version: 1.6.7594.29634
     For more information, please see http://wiki.ros.org/sw_urdf_exporter -->
<robot
  name="dorna_2_urdf">
  <link
    name="base_link">
    <inertial>
      <origin
        xyz="0.12698 1.4251E-06 0.055207"
        rpy="0 0 0" />
      <mass
        value="20.928" />
      <inertia
        ixx="0.60154"
        ixy="8.1377E-09"
        ixz="1.943E-05"
        iyy="0.62155"
        iyz="9.3581E-07"
        izz="1.1706" />
    </inertial>
    <visual>
      <origin
        xyz="0 0 0"
        rpy="0 0 0" />
      <geometry>
        <mesh
          filename="package://dorna_2_urdf/meshes/base_link.STL" />
      </geometry>
      <material
        name="">
        <color
          rgba="0.64706 0.61961 0.58824 1" />
      </material>
    </visual>
    <collision>
      <origin
        xyz="0 0 0"
        rpy="0 0 0" />
      <geometry>
        <mesh
          filename="package://dorna_2_urdf/meshes/base_link.STL" />
      </geometry>
    </collision>
  </link>
  <link
    name="Link_1">
    <inertial>
      <origin
        xyz="-0.022037 7.1084E-05 0.13277"
        rpy="0 0 0" />
      <mass
        value="0.70203" />
      <inertia
        ixx="0.0016762"
        ixy="0.00012689"
        ixz="-0.00047838"
        iyy="0.0028093"
        iyz="-3.1578E-05"
        izz="0.0029334" />
    </inertial>
    <visual>
      <origin
        xyz="0 0 0"
        rpy="0 0 0" />
      <geometry>
        <mesh
          filename="package://dorna_2_urdf/meshes/Link_1.STL" />
      </geometry>
      <material
        name="">
        <color
          rgba="0.79216 0.81961 0.93333 1" />
      </material>
    </visual>
    <collision>
      <origin
        xyz="0 0 0"
        rpy="0 0 0" />
      <geometry>
        <mesh
          filename="package://dorna_2_urdf/meshes/Link_1.STL" />
      </geometry>
    </collision>
  </link>
  <joint
    name="Joint_0"
    type="revolute">
    <origin
      xyz="0 0 0"
      rpy="0 0 0" />
    <parent
      link="base_link" />
    <child
      link="Link_1" />
    <axis
      xyz="0 0 1" />
    <limit
      lower="-2.7925"
      upper="3.1416"
      effort="10"
      velocity="10.472" />
  </joint>
  <link
    name="Link_2">
    <inertial>
      <origin
        xyz="0.033004 -0.047997 1.1969E-06"
        rpy="0 0 0" />
      <mass
        value="0.32464" />
      <inertia
        ixx="0.00048989"
        ixy="6.9763E-05"
        ixz="1.952E-08"
        iyy="0.0017419"
        iyz="-9.866E-09"
        izz="0.0020909" />
    </inertial>
    <visual>
      <origin
        xyz="0 0 0"
        rpy="0 0 0" />
      <geometry>
        <mesh
          filename="package://dorna_2_urdf/meshes/Link_2.STL" />
      </geometry>
      <material
        name="">
        <color
          rgba="0.79216 0.81961 0.93333 1" />
      </material>
    </visual>
    <collision>
      <origin
        xyz="0 0 0"
        rpy="0 0 0" />
      <geometry>
        <mesh
          filename="package://dorna_2_urdf/meshes/Link_2.STL" />
      </geometry>
    </collision>
  </link>
  <joint
    name="Joint_1"
    type="revolute">
    <origin
      xyz="0.095476 0.0508 0.20647"
      rpy="0 0 0" />
    <parent
      link="Link_1" />
    <child
      link="Link_2" />
    <axis
      xyz="0 1 0" />
    <limit
      lower="-1.5708"
      upper="3.1415"
      effort="10"
      velocity="7.854" />
  </joint>
  <link
    name="Link_3">
    <inertial>
      <origin
        xyz="0.021064 -0.042837 -6.2521E-08"
        rpy="0 0 0" />
      <mass
        value="0.27313" />
      <inertia
        ixx="0.00021713"
        ixy="2.2442E-05"
        ixz="3.6407E-08"
        iyy="0.00085068"
        iyz="-1.2633E-08"
        izz="0.00098072" />
    </inertial>
    <visual>
      <origin
        xyz="0 0 0"
        rpy="0 0 0" />
      <geometry>
        <mesh
          filename="package://dorna_2_urdf/meshes/Link_3.STL" />
      </geometry>
      <material
        name="">
        <color
          rgba="0.79216 0.81961 0.93333 1" />
      </material>
    </visual>
    <collision>
      <origin
        xyz="0 0 0"
        rpy="0 0 0" />
      <geometry>
        <mesh
          filename="package://dorna_2_urdf/meshes/Link_3.STL" />
      </geometry>
    </collision>
  </link>
  <joint
    name="Joint_2"
    type="revolute">
    <origin
      xyz="0.2032 -0.00635 0"
      rpy="0 0 0" />
    <parent
      link="Link_2" />
    <child
      link="Link_3" />
    <axis
      xyz="0 1 0" />
    <limit
      lower="-2.4784"
      upper="2.4784"
      effort="10"
      velocity="7.854" />
  </joint>
  <link
    name="Link_4">
    <inertial>
      <origin
        xyz="-5.9653E-10 -0.041275 -1.0071E-09"
        rpy="0 0 0" />
      <mass
        value="0.076836" />
      <inertia
        ixx="5.639E-05"
        ixy="-2.2838E-13"
        ixz="-6.7695E-14"
        iyy="1.719E-05"
        iyz="1.776E-12"
        izz="5.5885E-05" />
    </inertial>
    <visual>
      <origin
        xyz="0 0 0"
        rpy="0 0 0" />
      <geometry>
        <mesh
          filename="package://dorna_2_urdf/meshes/Link_4.STL" />
      </geometry>
      <material
        name="">
        <color
          rgba="0.79216 0.81961 0.93333 1" />
      </material>
    </visual>
    <collision>
      <origin
        xyz="0 0 0"
        rpy="0 0 0" />
      <geometry>
        <mesh
          filename="package://dorna_2_urdf/meshes/Link_4.STL" />
      </geometry>
    </collision>
  </link>
  <joint
    name="Joint_3"
    type="revolute">
    <origin
      xyz="0.1524 -0.003175 0"
      rpy="0 0 0" />
    <parent
      link="Link_3" />
    <child
      link="Link_4" />
    <axis
      xyz="0 -1 0" />
    <limit
      lower="-2.3562"
      upper="2.3562"
      effort="10"
      velocity="34.907" />
  </joint>
  <link
    name="Link_5">
    <inertial>
      <origin
        xyz="0.088867 -0.033145 -2.1341E-05"
        rpy="0 0 0" />
      <mass
        value="0.28989" />
      <inertia
        ixx="0.00010845"
        ixy="2.7205E-06"
        ixz="1.2546E-08"
        iyy="8.8784E-05"
        iyz="2.4118E-08"
        izz="0.00010988" />
    </inertial>
    <visual>
      <origin
        xyz="0 0 0"
        rpy="0 0 0" />
      <geometry>
        <mesh
          filename="package://dorna_2_urdf/meshes/Link_5.STL" />
      </geometry>
      <material
        name="">
        <color
          rgba="0.79216 0.81961 0.93333 1" />
      </material>
    </visual>
    <collision>
      <origin
        xyz="0 0 0"
        rpy="0 0 0" />
      <geometry>
        <mesh
          filename="package://dorna_2_urdf/meshes/Link_5.STL" />
      </geometry>
    </collision>
  </link>
  <joint
    name="Joint_4"
    type="continuous">
    <origin
      xyz="-0.021438 -0.041275 0"
      rpy="0 0 0" />
    <parent
      link="Link_4" />
    <child
      link="Link_5" />
    <axis
      xyz="-1 0 0" />
  </joint>
  <link
    name="Link_6">
    <inertial>
      <origin
        xyz="-9.5404E-06 0.051551 1.0778E-07"
        rpy="0 0 0" />
      <mass
        value="0.054936" />
      <inertia
        ixx="7.5563E-06"
        ixy="7.2422E-09"
        ixz="1.4116E-11"
        iyy="1.0764E-06"
        iyz="-1.4264E-10"
        izz="7.5041E-06" />
    </inertial>
    <visual>
      <origin
        xyz="0 0 0"
        rpy="0 0 0" />
      <geometry>
        <mesh
          filename="package://dorna_2_urdf/meshes/Link_6.STL" />
      </geometry>
      <material
        name="">
        <color
          rgba="0.64706 0.61961 0.58431 1" />
      </material>
    </visual>
    <collision>
      <origin
        xyz="0 0 0"
        rpy="0 0 0" />
      <geometry>
        <mesh
          filename="package://dorna_2_urdf/meshes/Link_6.STL" />
      </geometry>
    </collision>
  </link>
  <joint
    name="Joint_5"
    type="continuous">
    <origin
      xyz="0.097875 -0.12269 0"
      rpy="0 0 0" />
    <parent
      link="Link_5" />
    <child
      link="Link_6" />
    <axis
      xyz="0 1 0" />
  </joint>
</robot>